Workbook
Name Average: Pivot_Tables!$A$2:$E$9
Name Customer_Count: Pivot_Tables!$A$18:$B$53
Name Orders: Pivot_Tables!$A$10:$B$16

Sheet  Data
A1: Customer_ID | B1: Decision_Time(Sec) | C1: Scoop_Time(Sec) | D1: Checkout_Time(Sec) | E1: Total_Service_Time(Sec) | F1: Item | H1: Data Dictionary
A2: 1 | B2: 11.4 | C2: 29.54 | D2: 19.71 | E2: =SUM(C2:D2) -> 49.25 | F2: Cup | H2: Column | I2: Description
A3: 2 | B3: 8.68 | C3: 20.16 | D3: 21.21 | E3: =SUM(C3:D3) -> 41.37 | F3: Cone | H3: Customer_ID | I3: Sequential customer number
A4: 3 | B4: 41.98 | C4: 17.88 | D4: 16.73 | E4: =SUM(C4:D4) -> 34.61 | F4: Cup | H4: Decision_Time | I4: Time spent choosing an order
A5: 4 | B5: 12.59 | C5: 29.76 | D5: 25.44 | E5: =SUM(C5:D5) -> 55.2 | F5: Cone | H5: Scoop_Time | I5: Time spent preparing the order
A6: 5 | B6: 38.53 | C6: 13.81 | D6: 15.16 | E6: =SUM(C6:D6) -> 28.97 | F6: Cup | H6: Checkout_Time | I6: Time spent paying
A7: 6 | B7: 26.1 | C7: 9.6 | D7: 13.55 | E7: =SUM(C7:D7) -> 23.15 | F7: Cup | H7: Total_Service_Time | I7: Sum of all service stages
A8: 7 | B8: 14.83 | C8: 31.53 | D8: 16.58 | E8: =SUM(C8:D8) -> 48.11 | F8: Cup | H8: Item | I8: Product ordered
A9: 8 | B9: 33.13 | C9: 18.76 | D9: 24.09 | E9: =SUM(C9:D9) -> 42.85 | F9: Cup
A10: 9 | B10: 92.51 | C10: 42.34 | D10: 15.11 | E10: =SUM(C10:D10) -> 57.45 | F10: Cone
A11: 10 | B11: 30.51 | C11: 31.46 | D11: 17.66 | E11: =SUM(C11:D11) -> 49.12 | F11: Cone
A12: 11 | B12: 173.16 | C12: 49.94 | D12: 19.91 | E12: =SUM(C12:D12) -> 69.85 | F12: Cup
A13: 12 | B13: 19.23 | C13: 38.11 | D13: 25.08 | E13: =SUM(C13:D13) -> 63.19 | F13: Cone
A14: 13 | B14: 23.01 | C14: 14.35 | D14: 17.51 | E14: =SUM(C14:D14) -> 31.86 | F14: Cone
A15: 14 | B15: 9.9 | C15: 31.13 | D15: 24.73 | E15: =SUM(C15:D15) -> 55.86 | F15: Cone
A16: 15 | B16: 13.75 | C16: 30.2 | D16: 27.48 | E16: =SUM(C16:D16) -> 57.68 | F16: Cup
A17: 16 | B17: 138.86 | C17: 43.76 | D17: 21.31 | E17: =SUM(C17:D17) -> 65.07 | F17: Cone
A18: 17 | B18: 30.06 | C18: 19.05 | D18: 22.84 | E18: =SUM(C18:D18) -> 41.89 | F18: Cone
A19: 18 | B19: 44.05 | C19: 12.3 | D19: 27.78 | E19: =SUM(C19:D19) -> 40.08 | F19: Cone
A20: 19 | B20: 87.25 | C20: 106.7 | D20: 29.45 | E20: =SUM(C20:D20) -> 136.15 | F20: Cup
... A51: 50 | B51: 32.3 | C51: 40.5 | D51: 18.9 | E51: =SUM(C51:D51) -> 59.4 | F51: Sundae

Sheet Summary_Statistics
H2: Category | I2: Average Decision Time | J2: Average Scoop Time | K2: Average Checkout Time | L2: Average Service Time | O2: Cone | P2: Cup | Q2: Shake | R2: Split | S2: Sundae
H3: Overall | I3: =AVERAGE(Table1[Decision_Time(Sec)]) -> 37.4646 | J3: =AVERAGE(' Data'!C2:C51) -> 30.236 | K3: =AVERAGE(' Data'!D2:D51) -> 20.2 | L3: =SUM(J3:K3) -> 50.436 | O3: =COUNTIF(' Data'!F2:F51,"Cone") -> 25 | P3: =COUNTIF(' Data'!F2:F51,"Cup") -> 18 | Q3: =COUNTIF(' Data'!F2:F51,"Shake") -> 2 | R3: =COUNTIF(' Data'!F2:F51,"Split") -> 3 | S3: =COUNTIF(' Data'!F2:F51,"Sundae") -> 2
H4: Cup | I4: =AVERAGEIF(Table1[Item],H4,Table1[Decision_Time(Sec)]) -> 39.154444 | J4: =AVERAGEIF(Table1[Item],H4,Table1[Scoop_Time(Sec)]) -> 30.25 | K4: =AVERAGEIF(Table1[Item],H4,Table1[Checkout_Time(Sec)]) -> 20.26 | L4: =AVERAGEIF(Table1[Item],H4,Table1[Total_Service_Time(Sec)]) -> 50.51
H5: Cone | I5: =AVERAGEIF(Table1[Item],H5,Table1[Decision_Time(Sec)]) -> 36.064 | J5: =AVERAGEIF(Table1[Item],H5,Table1[Scoop_Time(Sec)]) -> 27.5932 | K5: =AVERAGEIF(Table1[Item],H5,Table1[Checkout_Time(Sec)]) -> 20.4976 | L5: =AVERAGEIF(Table1[Item],H5,Table1[Total_Service_Time(Sec)]) -> 48.0908
H6: Sundae | I6: =AVERAGEIF(Table1[Item],H6,Table1[Decision_Time(Sec)]) -> 46.75 | J6: =AVERAGEIF(Table1[Item],H6,Table1[Scoop_Time(Sec)]) -> 36.31 | K6: =AVERAGEIF(Table1[Item],H6,Table1[Checkout_Time(Sec)]) -> 19.985 | L6: =AVERAGEIF(Table1[Item],H6,Table1[Total_Service_Time(Sec)]) -> 56.295
H7: Shake | I7: =AVERAGEIF(Table1[Item],H7,Table1[Decision_Time(Sec)]) -> 39.705 | J7: =AVERAGEIF(Table1[Item],H7,Table1[Scoop_Time(Sec)]) -> 61.375 | K7: =AVERAGEIF(Table1[Item],H7,Table1[Checkout_Time(Sec)]) -> 19.335 | L7: =AVERAGEIF(Table1[Item],H7,Table1[Total_Service_Time(Sec)]) -> 80.71
H8: Split | I8: =AVERAGEIF(Table1[Item],H8,Table1[Decision_Time(Sec)]) -> 31.313333 | J8: =AVERAGEIF(Table1[Item],H8,Table1[Scoop_Time(Sec)]) -> 27.366667 | K8: =AVERAGEIF(Table1[Item],H8,Table1[Checkout_Time(Sec)]) -> 18.08 | L8: =AVERAGEIF(Table1[Item],H8,Table1[Total_Service_Time(Sec)]) -> 45.446667

Sheet Simulation
A1: Customer_ID | B1: Random_Number | C1: Item | D1: Decision_Time_sec | E1: Scoop_Time_sec | F1: Checkout_Time_sec | G1: Total_Service_Time_sec | H1: Service_Time_Bin | I1: Step 1 — Item Probabilities (from Original Data, n=50)
A2: =ROW()-1 -> 1 | B2: =RAND() -> 0.31188782 | C2: =IF(B2<=$L$3,$I$3,IF(B2<=$L$4,$I$4,IF(B2<=$L$5,$I$5,IF(B2<=$L$6,$I$6,$I$7)))) -> Cone | D2: =LOGINV(RAND(),$M$12,$L$12) -> 35.270977 | E2: =LOGINV(RAND(),$M$13,$L$13) -> 67.770523 | F2: =LOGINV(RAND(),$M$14,$L$14) -> 21.166198 | G2: =D2+E2+F2 -> 124.2077 | H2: =FLOOR(SimTable[[#This Row],[Total_Service_Time_sec]],10) -> 120 | I2: Item | J2: Count | K2: Probability | L2: Cumulative Probability
A3: =ROW()-1 -> 2 | B3: =RAND() -> 0.70597806 | C3: =IF(B3<=$L$3,$I$3,IF(B3<=$L$4,$I$4,IF(B3<=$L$5,$I$5,IF(B3<=$L$6,$I$6,$I$7)))) -> Cup | D3: =LOGINV(RAND(),$M$12,$L$12) -> 9.1545092 | E3: =LOGINV(RAND(),$M$13,$L$13) -> 54.906701 | F3: =LOGINV(RAND(),$M$14,$L$14) -> 13.59548 | G3: =D3+E3+F3 -> 77.656691 | H3: =FLOOR(SimTable[[#This Row],[Total_Service_Time_sec]],10) -> 70 | I3: Cone | J3: =COUNTIF(' Data'!F2:F51,I3) -> 25 | K3: =J3/$J$8 -> 0.5 | L3: =K3 -> 0.5
A4: =ROW()-1 -> 3 | B4: =RAND() -> 0.66440728 | C4: =IF(B4<=$L$3,$I$3,IF(B4<=$L$4,$I$4,IF(B4<=$L$5,$I$5,IF(B4<=$L$6,$I$6,$I$7)))) -> Cup | D4: =LOGINV(RAND(),$M$12,$L$12) -> 33.623652 | E4: =LOGINV(RAND(),$M$13,$L$13) -> 28.618733 | F4: =LOGINV(RAND(),$M$14,$L$14) -> 18.267622 | G4: =D4+E4+F4 -> 80.510007 | H4: =FLOOR(SimTable[[#This Row],[Total_Service_Time_sec]],10) -> 80 | I4: Cup | J4: =COUNTIF(' Data'!F2:F51,I4) -> 18 | K4: =J4/$J$8 -> 0.36 | L4: =L3+K4 -> 0.86
A5: =ROW()-1 -> 4 | B5: =RAND() -> 0.16047405 | C5: =IF(B5<=$L$3,$I$3,IF(B5<=$L$4,$I$4,IF(B5<=$L$5,$I$5,IF(B5<=$L$6,$I$6,$I$7)))) -> Cone | D5: =LOGINV(RAND(),$M$12,$L$12) -> 22.443948 | E5: =LOGINV(RAND(),$M$13,$L$13) -> 7.5970064 | F5: =LOGINV(RAND(),$M$14,$L$14) -> 17.918677 | G5: =D5+E5+F5 -> 47.959631 | H5: =FLOOR(SimTable[[#This Row],[Total_Service_Time_sec]],10) -> 40 | I5: Shake | J5: =COUNTIF(' Data'!F2:F51,I5) -> 2 | K5: =J5/$J$8 -> 0.04 | L5: =L4+K5 -> 0.9
A6: =ROW()-1 -> 5 | B6: =RAND() -> 0.73356934 | C6: =IF(B6<=$L$3,$I$3,IF(B6<=$L$4,$I$4,IF(B6<=$L$5,$I$5,IF(B6<=$L$6,$I$6,$I$7)))) -> Cup | D6: =LOGINV(RAND(),$M$12,$L$12) -> 55.966311 | E6: =LOGINV(RAND(),$M$13,$L$13) -> 23.364259 | F6: =LOGINV(RAND(),$M$14,$L$14) -> 17.750718 | G6: =D6+E6+F6 -> 97.081288 | H6: =FLOOR(SimTable[[#This Row],[Total_Service_Time_sec]],10) -> 90 | I6: Split | J6: =COUNTIF(' Data'!F2:F51,I6) -> 3 | K6: =J6/$J$8 -> 0.06 | L6: =L5+K6 -> 0.96
A7: =ROW()-1 -> 6 | B7: =RAND() -> 0.45433922 | C7: =IF(B7<=$L$3,$I$3,IF(B7<=$L$4,$I$4,IF(B7<=$L$5,$I$5,IF(B7<=$L$6,$I$6,$I$7)))) -> Cone | D7: =LOGINV(RAND(),$M$12,$L$12) -> 44.899083 | E7: =LOGINV(RAND(),$M$13,$L$13) -> 11.96807 | F7: =LOGINV(RAND(),$M$14,$L$14) -> 14.905294 | G7: =D7+E7+F7 -> 71.772447 | H7: =FLOOR(SimTable[[#This Row],[Total_Service_Time_sec]],10) -> 70 | I7: Sundae | J7: =COUNTIF(' Data'!F2:F51,I7) -> 2 | K7: =J7/$J$8 -> 0.04 | L7: =L6+K7 -> 1
A8: =ROW()-1 -> 7 | B8: =RAND() -> 0.48257604 | C8: =IF(B8<=$L$3,$I$3,IF(B8<=$L$4,$I$4,IF(B8<=$L$5,$I$5,IF(B8<=$L$6,$I$6,$I$7)))) -> Cone | D8: =LOGINV(RAND(),$M$12,$L$12) -> 47.600033 | E8: =LOGINV(RAND(),$M$13,$L$13) -> 16.069575 | F8: =LOGINV(RAND(),$M$14,$L$14) -> 18.662418 | G8: =D8+E8+F8 -> 82.332026 | H8: =FLOOR(SimTable[[#This Row],[Total_Service_Time_sec]],10) -> 80 | I8: Total | J8: =SUM(J3:J7) -> 50 | K8: =SUM(K3:K7) -> 1
A9: =ROW()-1 -> 8 | B9: =RAND() -> 0.52191044 | C9: =IF(B9<=$L$3,$I$3,IF(B9<=$L$4,$I$4,IF(B9<=$L$5,$I$5,IF(B9<=$L$6,$I$6,$I$7)))) -> Cup | D9: =LOGINV(RAND(),$M$12,$L$12) -> 77.51411 | E9: =LOGINV(RAND(),$M$13,$L$13) -> 60.985987 | F9: =LOGINV(RAND(),$M$14,$L$14) -> 28.043888 | G9: =D9+E9+F9 -> 166.54398 | H9: =FLOOR(SimTable[[#This Row],[Total_Service_Time_sec]],10) -> 160
A10: =ROW()-1 -> 9 | B10: =RAND() -> 0.019173668 | C10: =IF(B10<=$L$3,$I$3,IF(B10<=$L$4,$I$4,IF(B10<=$L$5,$I$5,IF(B10<=$L$6,$I$6,$I$7)))) -> Cone | D10: =LOGINV(RAND(),$M$12,$L$12) -> 70.387911 | E10: =LOGINV(RAND(),$M$13,$L$13) -> 18.253459 | F10: =LOGINV(RAND(),$M$14,$L$14) -> 15.490332 | G10: =D10+E10+F10 -> 104.1317 | H10: =FLOOR(SimTable[[#This Row],[Total_Service_Time_sec]],10) -> 100 | I10: Step 2 — Time Distribution Parameters (Lognormal, from Original Data, n=50)
A11: =ROW()-1 -> 10 | B11: =RAND() -> 0.10654465 | C11: =IF(B11<=$L$3,$I$3,IF(B11<=$L$4,$I$4,IF(B11<=$L$5,$I$5,IF(B11<=$L$6,$I$6,$I$7)))) -> Cone | D11: =LOGINV(RAND(),$M$12,$L$12) -> 36.200943 | E11: =LOGINV(RAND(),$M$13,$L$13) -> 26.718887 | F11: =LOGINV(RAND(),$M$14,$L$14) -> 17.575038 | G11: =D11+E11+F11 -> 80.494868 | H11: =FLOOR(SimTable[[#This Row],[Total_Service_Time_sec]],10) -> 80 | I11: Metric | J11: Mean (sec) | K11: Std Dev (sec) | L11: Log SD (σ) | M11: Log Mean (μ)
A12: =ROW()-1 -> 11 | B12: =RAND() -> 0.097739769 | C12: =IF(B12<=$L$3,$I$3,IF(B12<=$L$4,$I$4,IF(B12<=$L$5,$I$5,IF(B12<=$L$6,$I$6,$I$7)))) -> Cone | D12: =LOGINV(RAND(),$M$12,$L$12) -> 62.249091 | E12: =LOGINV(RAND(),$M$13,$L$13) -> 25.507699 | F12: =LOGINV(RAND(),$M$14,$L$14) -> 21.692617 | G12: =D12+E12+F12 -> 109.44941 | H12: =FLOOR(SimTable[[#This Row],[Total_Service_Time_sec]],10) -> 100 | I12: Decision Time | J12: =AVERAGE(' Data'!B2:B51) -> 37.4646 | K12: =STDEV(' Data'!B2:B51) -> 30.17223 | L12: =SQRT(LN(1+(K12/J12)^2)) -> 0.70705199 | M12: =LN(J12)-(L12^2)/2 -> 3.3734352
A13: =ROW()-1 -> 12 | B13: =RAND() -> 0.79471486 | C13: =IF(B13<=$L$3,$I$3,IF(B13<=$L$4,$I$4,IF(B13<=$L$5,$I$5,IF(B13<=$L$6,$I$6,$I$7)))) -> Cup | D13: =LOGINV(RAND(),$M$12,$L$12) -> 76.166445 | E13: =LOGINV(RAND(),$M$13,$L$13) -> 20.958658 | F13: =LOGINV(RAND(),$M$14,$L$14) -> 13.854301 | G13: =D13+E13+F13 -> 110.9794 | H13: =FLOOR(SimTable[[#This Row],[Total_Service_Time_sec]],10) -> 110 | I13: Scoop Time | J13: =AVERAGE(' Data'!C2:C51) -> 30.236 | K13: =STDEV(' Data'!C2:C51) -> 17.64903 | L13: =SQRT(LN(1+(K13/J13)^2)) -> 0.54148321 | M13: =LN(J13)-(L13^2)/2 -> 3.2624312 | P13: A | Q13: B | R13: C | S13: D
A14: =ROW()-1 -> 13 | B14: =RAND() -> 0.82350639 | C14: =IF(B14<=$L$3,$I$3,IF(B14<=$L$4,$I$4,IF(B14<=$L$5,$I$5,IF(B14<=$L$6,$I$6,$I$7)))) -> Cup | D14: =LOGINV(RAND(),$M$12,$L$12) -> 10.417837 | E14: =LOGINV(RAND(),$M$13,$L$13) -> 48.865907 | F14: =LOGINV(RAND(),$M$14,$L$14) -> 17.430087 | G14: =D14+E14+F14 -> 76.713831 | H14: =FLOOR(SimTable[[#This Row],[Total_Service_Time_sec]],10) -> 70 | I14: Checkout Time | J14: =AVERAGE(' Data'!D2:D51) -> 20.2 | K14: =STDEV(' Data'!D2:D51) -> 3.7770002 | L14: =SQRT(LN(1+(K14/J14)^2)) -> 0.18537617 | M14: =LN(J14)-(L14^2)/2 -> 2.9885004 | P14: Metric | Q14: Mean | R14: SD | S14: CV
A15: =ROW()-1 -> 14 | B15: =RAND() -> 0.66590907 | C15: =IF(B15<=$L$3,$I$3,IF(B15<=$L$4,$I$4,IF(B15<=$L$5,$I$5,IF(B15<=$L$6,$I$6,$I$7)))) -> Cup | D15: =LOGINV(RAND(),$M$12,$L$12) -> 10.116641 | E15: =LOGINV(RAND(),$M$13,$L$13) -> 41.693689 | F15: =LOGINV(RAND(),$M$14,$L$14) -> 19.128777 | G15: =D15+E15+F15 -> 70.939107 | H15: =FLOOR(SimTable[[#This Row],[Total_Service_Time_sec]],10) -> 70 | P15: Decision Time | Q15: =AVERAGE(Simulation!D:D) -> 38.069895 | R15: =_xlfn.STDEV.S(Simulation!D:D) -> 31.133983 | S15: =Q15/R15 -> 1.2227762
A16: =ROW()-1 -> 15 | B16: =RAND() -> 0.60909679 | C16: =IF(B16<=$L$3,$I$3,IF(B16<=$L$4,$I$4,IF(B16<=$L$5,$I$5,IF(B16<=$L$6,$I$6,$I$7)))) -> Cup | D16: =LOGINV(RAND(),$M$12,$L$12) -> 15.721661 | E16: =LOGINV(RAND(),$M$13,$L$13) -> 30.625513 | F16: =LOGINV(RAND(),$M$14,$L$14) -> 18.56677 | G16: =D16+E16+F16 -> 64.913943 | H16: =FLOOR(SimTable[[#This Row],[Total_Service_Time_sec]],10) -> 60 | I16: Note: Decision/Scoop/Checkout are simulated from a Lognormal distribution via LOGINV(RAND(), μ, σ) — the log-space mean and SD, derived from the observed arithmetic mean/SD (columns J:K) using σ=SQRT(LN(1+(SD/Mean)^2)), μ=LN(Mean)-σ²/2. Lognormal keeps every simulated time positive and matches the right-skewed shape of the observed service-time data. Total_Service_Time = Decision + Scoop + Checkout. | P16: Scoop Time | Q16: =AVERAGE(Simulation!E:E) -> 30.122265 | R16: =_xlfn.STDEV.S(Simulation!E:E) -> 17.437028 | S16: =Q16/R16 -> 1.7274884
A17: =ROW()-1 -> 16 | B17: =RAND() -> 0.627894 | C17: =IF(B17<=$L$3,$I$3,IF(B17<=$L$4,$I$4,IF(B17<=$L$5,$I$5,IF(B17<=$L$6,$I$6,$I$7)))) -> Cup | D17: =LOGINV(RAND(),$M$12,$L$12) -> 39.421022 | E17: =LOGINV(RAND(),$M$13,$L$13) -> 29.768226 | F17: =LOGINV(RAND(),$M$14,$L$14) -> 23.38007 | G17: =D17+E17+F17 -> 92.569318 | H17: =FLOOR(SimTable[[#This Row],[Total_Service_Time_sec]],10) -> 90 | P17: Checkout Time | Q17: =AVERAGE(Simulation!F:F) -> 20.180122 | R17: =_xlfn.STDEV.S(Simulation!F:F) -> 3.7138065 | S17: =Q17/R17 -> 5.4338107
A18: =ROW()-1 -> 17 | B18: =RAND() -> 0.95599351 | C18: =IF(B18<=$L$3,$I$3,IF(B18<=$L$4,$I$4,IF(B18<=$L$5,$I$5,IF(B18<=$L$6,$I$6,$I$7)))) -> Split | D18: =LOGINV(RAND(),$M$12,$L$12) -> 22.044286 | E18: =LOGINV(RAND(),$M$13,$L$13) -> 47.108553 | F18: =LOGINV(RAND(),$M$14,$L$14) -> 20.200597 | G18: =D18+E18+F18 -> 89.353436 | H18: =FLOOR(SimTable[[#This Row],[Total_Service_Time_sec]],10) -> 80 | P18: Total Service Time | Q18: =AVERAGE(Simulation!G:G) -> 88.372281 | R18: =_xlfn.STDEV.S(Simulation!G:G) -> 36.155766 | S18: =Q18/R18 -> 2.4442099
A19: =ROW()-1 -> 18 | B19: =RAND() -> 0.70607326 | C19: =IF(B19<=$L$3,$I$3,IF(B19<=$L$4,$I$4,IF(B19<=$L$5,$I$5,IF(B19<=$L$6,$I$6,$I$7)))) -> Cup | D19: =LOGINV(RAND(),$M$12,$L$12) -> 33.282004 | E19: =LOGINV(RAND(),$M$13,$L$13) -> 39.797974 | F19: =LOGINV(RAND(),$M$14,$L$14) -> 23.963254 | G19: =D19+E19+F19 -> 97.043232 | H19: =FLOOR(SimTable[[#This Row],[Total_Service_Time_sec]],10) -> 90
A20: =ROW()-1 -> 19 | B20: =RAND() -> 0.43127345 | C20: =IF(B20<=$L$3,$I$3,IF(B20<=$L$4,$I$4,IF(B20<=$L$5,$I$5,IF(B20<=$L$6,$I$6,$I$7)))) -> Cone | D20: =LOGINV(RAND(),$M$12,$L$12) -> 21.535435 | E20: =LOGINV(RAND(),$M$13,$L$13) -> 32.297678 | F20: =LOGINV(RAND(),$M$14,$L$14) -> 17.688119 | G20: =D20+E20+F20 -> 71.521232 | H20: =FLOOR(SimTable[[#This Row],[Total_Service_Time_sec]],10) -> 70 | I20: Step 3 — Validation: Simulated vs Original
A21: =ROW()-1 -> 20 | B21: =RAND() -> 0.92083276 | C21: =IF(B21<=$L$3,$I$3,IF(B21<=$L$4,$I$4,IF(B21<=$L$5,$I$5,IF(B21<=$L$6,$I$6,$I$7)))) -> Split | D21: =LOGINV(RAND(),$M$12,$L$12) -> 13.492315 | E21: =LOGINV(RAND(),$M$13,$L$13) -> 11.939599 | F21: =LOGINV(RAND(),$M$14,$L$14) -> 13.223069 | G21: =D21+E21+F21 -> 38.654983 | H21: =FLOOR(SimTable[[#This Row],[Total_Service_Time_sec]],10) -> 30 | I21: Metric | J21: Original Mean | K21: Simulated Mean (n=5,000) | L21: Difference
A22: =ROW()-1 -> 21 | B22: =RAND() -> 0.66368163 | C22: =IF(B22<=$L$3,$I$3,IF(B22<=$L$4,$I$4,IF(B22<=$L$5,$I$5,IF(B22<=$L$6,$I$6,$I$7)))) -> Cup | D22: =LOGINV(RAND(),$M$12,$L$12) -> 32.947654 | E22: =LOGINV(RAND(),$M$13,$L$13) -> 9.6272589 | F22: =LOGINV(RAND(),$M$14,$L$14) -> 19.548677 | G22: =D22+E22+F22 -> 62.12359 | H22: =FLOOR(SimTable[[#This Row],[Total_Service_Time_sec]],10) -> 60 | I22: Decision Time | J22: =$J$12 -> 37.4646 | K22: =AVERAGE(D2:D5001) -> 38.069895 | L22: =K22-J22 -> 0.60529494
A23: =ROW()-1 -> 22 | B23: =RAND() -> 0.76766601 | C23: =IF(B23<=$L$3,$I$3,IF(B23<=$L$4,$I$4,IF(B23<=$L$5,$I$5,IF(B23<=$L$6,$I$6,$I$7)))) -> Cup | D23: =LOGINV(RAND(),$M$12,$L$12) -> 112.22417 | E23: =LOGINV(RAND(),$M$13,$L$13) -> 21.009776 | F23: =LOGINV(RAND(),$M$14,$L$14) -> 19.597667 | G23: =D23+E23+F23 -> 152.83161 | H23: =FLOOR(SimTable[[#This Row],[Total_Service_Time_sec]],10) -> 150 | I23: Scoop Time | J23: =$J$13 -> 30.236 | K23: =AVERAGE(E2:E5001) -> 30.122265 | L23: =K23-J23 -> -0.11373546
A24: =ROW()-1 -> 23 | B24: =RAND() -> 0.98310767 | C24: =IF(B24<=$L$3,$I$3,IF(B24<=$L$4,$I$4,IF(B24<=$L$5,$I$5,IF(B24<=$L$6,$I$6,$I$7)))) -> Sundae | D24: =LOGINV(RAND(),$M$12,$L$12) -> 24.726433 | E24: =LOGINV(RAND(),$M$13,$L$13) -> 30.772848 | F24: =LOGINV(RAND(),$M$14,$L$14) -> 20.015548 | G24: =D24+E24+F24 -> 75.514829 | H24: =FLOOR(SimTable[[#This Row],[Total_Service_Time_sec]],10) -> 70 | I24: Checkout Time | J24: =$J$14 -> 20.2 | K24: =AVERAGE(F2:F5001) -> 20.180122 | L24: =K24-J24 -> -0.019878237
A25: =ROW()-1 -> 24 | B25: =RAND() -> 0.11690091 | C25: =IF(B25<=$L$3,$I$3,IF(B25<=$L$4,$I$4,IF(B25<=$L$5,$I$5,IF(B25<=$L$6,$I$6,$I$7)))) -> Cone | D25: =LOGINV(RAND(),$M$12,$L$12) -> 63.132572 | E25: =LOGINV(RAND(),$M$13,$L$13) -> 28.836223 | F25: =LOGINV(RAND(),$M$14,$L$14) -> 22.880111 | G25: =D25+E25+F25 -> 114.84891 | H25: =FLOOR(SimTable[[#This Row],[Total_Service_Time_sec]],10) -> 110 | I25: Total Service Time | J25: =J12+J13+J14 -> 87.9006 | K25: =AVERAGE(G2:G5001) -> 88.372281 | L25: =K25-J25 -> 0.47168124
A26: =ROW()-1 -> 25 | B26: =RAND() -> 0.26728141 | C26: =IF(B26<=$L$3,$I$3,IF(B26<=$L$4,$I$4,IF(B26<=$L$5,$I$5,IF(B26<=$L$6,$I$6,$I$7)))) -> Cone | D26: =LOGINV(RAND(),$M$12,$L$12) -> 25.329855 | E26: =LOGINV(RAND(),$M$13,$L$13) -> 36.962346 | F26: =LOGINV(RAND(),$M$14,$L$14) -> 14.971357 | G26: =D26+E26+F26 -> 77.263557 | H26: =FLOOR(SimTable[[#This Row],[Total_Service_Time_sec]],10) -> 70
A27: =ROW()-1 -> 26 | B27: =RAND() -> 0.36400409 | C27: =IF(B27<=$L$3,$I$3,IF(B27<=$L$4,$I$4,IF(B27<=$L$5,$I$5,IF(B27<=$L$6,$I$6,$I$7)))) -> Cone | D27: =LOGINV(RAND(),$M$12,$L$12) -> 43.818967 | E27: =LOGINV(RAND(),$M$13,$L$13) -> 50.791653 | F27: =LOGINV(RAND(),$M$14,$L$14) -> 16.851499 | G27: =D27+E27+F27 -> 111.46212 | H27: =FLOOR(SimTable[[#This Row],[Total_Service_Time_sec]],10) -> 110 | I27: Item Probability Check
A28: =ROW()-1 -> 27 | B28: =RAND() -> 0.36655939 | C28: =IF(B28<=$L$3,$I$3,IF(B28<=$L$4,$I$4,IF(B28<=$L$5,$I$5,IF(B28<=$L$6,$I$6,$I$7)))) -> Cone | D28: =LOGINV(RAND(),$M$12,$L$12) -> 45.603653 | E28: =LOGINV(RAND(),$M$13,$L$13) -> 25.892998 | F28: =LOGINV(RAND(),$M$14,$L$14) -> 17.303161 | G28: =D28+E28+F28 -> 88.799812 | H28: =FLOOR(SimTable[[#This Row],[Total_Service_Time_sec]],10) -> 80 | I28: Item | J28: Original % | K28: Simulated % | L28: Difference
A29: =ROW()-1 -> 28 | B29: =RAND() -> 0.39597876 | C29: =IF(B29<=$L$3,$I$3,IF(B29<=$L$4,$I$4,IF(B29<=$L$5,$I$5,IF(B29<=$L$6,$I$6,$I$7)))) -> Cone | D29: =LOGINV(RAND(),$M$12,$L$12) -> 14.168529 | E29: =LOGINV(RAND(),$M$13,$L$13) -> 11.045232 | F29: =LOGINV(RAND(),$M$14,$L$14) -> 19.465093 | G29: =D29+E29+F29 -> 44.678855 | H29: =FLOOR(SimTable[[#This Row],[Total_Service_Time_sec]],10) -> 40 | I29: =I3 -> Cone | J29: =K3 -> 0.5 | K29: =COUNTIF(C2:C5001,I29)/5000 -> 0.5038 | L29: =K29-J29 -> 0.0038
A30: =ROW()-1 -> 29 | B30: =RAND() -> 0.21784084 | C30: =IF(B30<=$L$3,$I$3,IF(B30<=$L$4,$I$4,IF(B30<=$L$5,$I$5,IF(B30<=$L$6,$I$6,$I$7)))) -> Cone | D30: =LOGINV(RAND(),$M$12,$L$12) -> 19.792876 | E30: =LOGINV(RAND(),$M$13,$L$13) -> 20.415367 | F30: =LOGINV(RAND(),$M$14,$L$14) -> 21.168622 | G30: =D30+E30+F30 -> 61.376865 | H30: =FLOOR(SimTable[[#This Row],[Total_Service_Time_sec]],10) -> 60 | I30: =I4 -> Cup | J30: =K4 -> 0.36 | K30: =COUNTIF(C2:C5001,I30)/5000 -> 0.361 | L30: =K30-J30 -> 0.001
A31: =ROW()-1 -> 30 | B31: =RAND() -> 0.43325078 | C31: =IF(B31<=$L$3,$I$3,IF(B31<=$L$4,$I$4,IF(B31<=$L$5,$I$5,IF(B31<=$L$6,$I$6,$I$7)))) -> Cone | D31: =LOGINV(RAND(),$M$12,$L$12) -> 20.680261 | E31: =LOGINV(RAND(),$M$13,$L$13) -> 30.302505 | F31: =LOGINV(RAND(),$M$14,$L$14) -> 22.026547 | G31: =D31+E31+F31 -> 73.009313 | H31: =FLOOR(SimTable[[#This Row],[Total_Service_Time_sec]],10) -> 70 | I31: =I5 -> Shake | J31: =K5 -> 0.04 | K31: =COUNTIF(C2:C5001,I31)/5000 -> 0.038 | L31: =K31-J31 -> -0.002
A32: =ROW()-1 -> 31 | B32: =RAND() -> 0.23424237 | C32: =IF(B32<=$L$3,$I$3,IF(B32<=$L$4,$I$4,IF(B32<=$L$5,$I$5,IF(B32<=$L$6,$I$6,$I$7)))) -> Cone | D32: =LOGINV(RAND(),$M$12,$L$12) -> 23.97768 | E32: =LOGINV(RAND(),$M$13,$L$13) -> 36.182719 | F32: =LOGINV(RAND(),$M$14,$L$14) -> 22.057394 | G32: =D32+E32+F32 -> 82.217792 | H32: =FLOOR(SimTable[[#This Row],[Total_Service_Time_sec]],10) -> 80 | I32: =I6 -> Split | J32: =K6 -> 0.06 | K32: =COUNTIF(C2:C5001,I32)/5000 -> 0.0602 | L32: =K32-J32 -> 0.0002
A33: =ROW()-1 -> 32 | B33: =RAND() -> 0.73732924 | C33: =IF(B33<=$L$3,$I$3,IF(B33<=$L$4,$I$4,IF(B33<=$L$5,$I$5,IF(B33<=$L$6,$I$6,$I$7)))) -> Cup | D33: =LOGINV(RAND(),$M$12,$L$12) -> 26.936314 | E33: =LOGINV(RAND(),$M$13,$L$13) -> 24.771874 | F33: =LOGINV(RAND(),$M$14,$L$14) -> 20.473788 | G33: =D33+E33+F33 -> 72.181976 | H33: =FLOOR(SimTable[[#This Row],[Total_Service_Time_sec]],10) -> 70 | I33: =I7 -> Sundae | J33: =K7 -> 0.04 | K33: =COUNTIF(C2:C5001,I33)/5000 -> 0.037 | L33: =K33-J33 -> -0.003
A34: =ROW()-1 -> 33 | B34: =RAND() -> 0.029632473 | C34: =IF(B34<=$L$3,$I$3,IF(B34<=$L$4,$I$4,IF(B34<=$L$5,$I$5,IF(B34<=$L$6,$I$6,$I$7)))) -> Cone | D34: =LOGINV(RAND(),$M$12,$L$12) -> 67.885219 | E34: =LOGINV(RAND(),$M$13,$L$13) -> 14.974676 | F34: =LOGINV(RAND(),$M$14,$L$14) -> 19.71443 | G34: =D34+E34+F34 -> 102.57433 | H34: =FLOOR(SimTable[[#This Row],[Total_Service_Time_sec]],10) -> 100
A35: =ROW()-1 -> 34 | B35: =RAND() -> 0.18709522 | C35: =IF(B35<=$L$3,$I$3,IF(B35<=$L$4,$I$4,IF(B35<=$L$5,$I$5,IF(B35<=$L$6,$I$6,$I$7)))) -> Cone | D35: =LOGINV(RAND(),$M$12,$L$12) -> 24.534093 | E35: =LOGINV(RAND(),$M$13,$L$13) -> 26.285067 | F35: =LOGINV(RAND(),$M$14,$L$14) -> 17.577522 | G35: =D35+E35+F35 -> 68.396682 | H35: =FLOOR(SimTable[[#This Row],[Total_Service_Time_sec]],10) -> 60
A36: =ROW()-1 -> 35 | B36: =RAND() -> 0.96893867 | C36: =IF(B36<=$L$3,$I$3,IF(B36<=$L$4,$I$4,IF(B36<=$L$5,$I$5,IF(B36<=$L$6,$I$6,$I$7)))) -> Sundae | D36: =LOGINV(RAND(),$M$12,$L$12) -> 47.786681 | E36: =LOGINV(RAND(),$M$13,$L$13) -> 38.34794 | F36: =LOGINV(RAND(),$M$14,$L$14) -> 20.117707 | G36: =D36+E36+F36 -> 106.25233 | H36: =FLOOR(SimTable[[#This Row],[Total_Service_Time_sec]],10) -> 100
A37: =ROW()-1 -> 36 | B37: =RAND() -> 0.19109545 | C37: =IF(B37<=$L$3,$I$3,IF(B37<=$L$4,$I$4,IF(B37<=$L$5,$I$5,IF(B37<=$L$6,$I$6,$I$7)))) -> Cone | D37: =LOGINV(RAND(),$M$12,$L$12) -> 45.176211 | E37: =LOGINV(RAND(),$M$13,$L$13) -> 28.740104 | F37: =LOGINV(RAND(),$M$14,$L$14) -> 19.781752 | G37: =D37+E37+F37 -> 93.698067 | H37: =FLOOR(SimTable[[#This Row],[Total_Service_Time_sec]],10) -> 90
A38: =ROW()-1 -> 37 | B38: =RAND() -> 0.77054918 | C38: =IF(B38<=$L$3,$I$3,IF(B38<=$L$4,$I$4,IF(B38<=$L$5,$I$5,IF(B38<=$L$6,$I$6,$I$7)))) -> Cup | D38: =LOGINV(RAND(),$M$12,$L$12) -> 34.796373 | E38: =LOGINV(RAND(),$M$13,$L$13) -> 30.757759 | F38: =LOGINV(RAND(),$M$14,$L$14) -> 17.40307 | G38: =D38+E38+F38 -> 82.957202 | H38: =FLOOR(SimTable[[#This Row],[Total_Service_Time_sec]],10) -> 80
A39: =ROW()-1 -> 38 | B39: =RAND() -> 0.44421484 | C39: =IF(B39<=$L$3,$I$3,IF(B39<=$L$4,$I$4,IF(B39<=$L$5,$I$5,IF(B39<=$L$6,$I$6,$I$7)))) -> Cone | D39: =LOGINV(RAND(),$M$12,$L$12) -> 51.245237 | E39: =LOGINV(RAND(),$M$13,$L$13) -> 57.217974 | F39: =LOGINV(RAND(),$M$14,$L$14) -> 14.917612 | G39: =D39+E39+F39 -> 123.38082 | H39: =FLOOR(SimTable[[#This Row],[Total_Service_Time_sec]],10) -> 120
A40: =ROW()-1 -> 39 | B40: =RAND() -> 0.095858584 | C40: =IF(B40<=$L$3,$I$3,IF(B40<=$L$4,$I$4,IF(B40<=$L$5,$I$5,IF(B40<=$L$6,$I$6,$I$7)))) -> Cone | D40: =LOGINV(RAND(),$M$12,$L$12) -> 32.630881 | E40: =LOGINV(RAND(),$M$13,$L$13) -> 35.934902 | F40: =LOGINV(RAND(),$M$14,$L$14) -> 23.659475 | G40: =D40+E40+F40 -> 92.225258 | H40: =FLOOR(SimTable[[#This Row],[Total_Service_Time_sec]],10) -> 90
...

Sheet Pivot_Tables
A2: Items | B2: Average Decision | C2: Average Scoop | D2: Average Checkout | E2: Average Total
A3: Cone | B3: 36.839404 | C3: 30.560135 | D3: 20.12287 | E3: 87.522409
A4: Cup | B4: 38.309713 | C4: 30.000118 | D4: 20.307423 | E4: 88.617254
A5: Shake | B5: 37.856404 | C5: 29.854427 | D5: 20.298344 | E5: 88.009175
A6: Split | B6: 38.412039 | C6: 29.897291 | D6: 20.026118 | E6: 88.335448
A7: Sundae | B7: 37.272546 | C7: 28.889001 | D7: 20.156772 | E7: 86.31832
A8: Grand Total | B8: 37.535622 | C8: 30.219797 | D8: 20.19387 | E8: 87.949288
A9: Minutes | B9: =GETPIVOTDATA("Average Decision ",$A$2)/60 -> 0.62559369 | C9: =GETPIVOTDATA("Average Scoop",$A$2)/60 -> 0.50366328 | D9: =GETPIVOTDATA("Average Checkout",$A$2)/60 -> 0.3365645 | E9: =GETPIVOTDATA("Average Total",$A$2)/60 -> 1.4658215
A10: Item | B10: Orders
A11: Cone | B11: 2457
A12: Cup | B12: 1870
A13: Shake | B13: 180
A14: Split | B14: 294
A15: Sundae | B15: 199
A16: Grand Total | B16: 5000
A18: Service Time | B18: Count of Customers
A19: 20 | B19: 2
A20: 30 | B20: 44
A21: 40 | B21: 307
A22: 50 | B22: 581
A23: 60 | B23: 750
A24: 70 | B24: 797
A25: 80 | B25: 648
A26: 90 | B26: 507
A27: 100 | B27: 376
A28: 110 | B28: 276
A29: 120 | B29: 192
A30: 130 | B30: 134
... A52: 520 | B52: 1
A53: Grand Total | B53: 5000

Sheet Excel_Dashboard
A1: KPI | B1: Values
A2: Average Decision Time | B2: =Pivot_Tables!B9 -> 0.62559369
A3: Average Scoop Time | B3: =Pivot_Tables!C9 -> 0.50366328
A4: Average Checkout Time | B4: =Pivot_Tables!D9 -> 0.3365645
A5: Average Total Service Time | B5: =Pivot_Tables!E9 -> 1.4658215

Sheet Arrival_Rates_Reference
A1: Friday
A2: Time | B2: Avg Customer/hour
A3: 6pm-7pm | B3: 94
A4: 7pm-8pm | B4: 134
A5: 8pm-9pm | B5: 120
A6: 9pm-10pm | B6: 107
A7: 10pm-11pm | B7: 120
A8: Average 6-11pm | B8: =AVERAGE(B3:B7) -> 115
A10: Saturday
A11: Time | B11: Avg Customer/hour
A12: 2pm-6pm | B12: 70
A13: 6pm-7pm | B13: 103
A14: 7pm-8pm | B14: 134
A15: 8pm-11pm | B15: 164
A16: Average | B16: =AVERAGE(B12:B15) -> 117.75
A18: Sunday
A19: Time | B19: Avg Customer/hour
A20: 2pm-10pm | B20: 120
